<?xml version="1.0" ?>
<sdf version="1.8">
  <model name="tfg_robot">
    <pose>0 0 0.2 0 0 0</pose>

    <link name="base_link">
      <inertial>
        <mass>5.0</mass>
        <inertia>
          <ixx>0.1</ixx>
          <iyy>0.1</iyy>
          <izz>0.1</izz>
        </inertia>
      </inertial>

      <collision name="base_collision">
        <geometry>
          <box>
            <size>0.45 0.35 0.2</size>
          </box>
        </geometry>
      </collision>

      <visual name="base_visual">
        <geometry>
          <box>
            <size>0.45 0.35 0.2</size>
          </box>
        </geometry>
        <material>
          <ambient>0.1 0.1 0.8 1</ambient>
          <diffuse>0.1 0.1 0.8 1</diffuse>
        </material>
      </visual>
    </link>

    <link name="left_wheel">
      <pose>0 0.22 0.08 1.5708 0 0</pose>
      <inertial>
        <mass>0.5</mass>
      </inertial>
      <collision name="collision">
        <geometry>
          <cylinder>
            <radius>0.08</radius>
            <length>0.05</length>
          </cylinder>
        </geometry>
      </collision>
      <visual name="visual">
        <geometry>
          <cylinder>
            <radius>0.08</radius>
            <length>0.05</length>
          </cylinder>
        </geometry>
      </visual>
    </link>

    <link name="right_wheel">
      <pose>0 -0.22 0.08 1.5708 0 0</pose>
      <inertial>
        <mass>0.5</mass>
      </inertial>
      <collision name="collision">
        <geometry>
          <cylinder>
            <radius>0.08</radius>
            <length>0.05</length>
          </cylinder>
        </geometry>
      </collision>
      <visual name="visual">
        <geometry>
          <cylinder>
            <radius>0.08</radius>
            <length>0.05</length>
          </cylinder>
        </geometry>
      </visual>
    </link>

    <joint name="left_wheel_joint" type="revolute">
      <parent>base_link</parent>
      <child>left_wheel</child>
      <axis>
        <xyz>1 0 1</xyz>
      </axis>
    </joint>

    <joint name="right_wheel_joint" type="revolute">
      <parent>base_link</parent>
      <child>right_wheel</child>
      <axis>
        <xyz>1 0 1</xyz>
      </axis>
    </joint>

    <link name="lidar_link">
      <pose>0 0 0.30 0 0 0</pose>

 <sensor name="hls_lfcd_lds" type="gpu_lidar">
  <always_on>true</always_on>
  <visualize>true</visualize>
  <update_rate>10</update_rate>
  <topic>scan</topic>

  <lidar>
    <scan>
      <horizontal>
        <samples>360</samples>
        <resolution>1</resolution>
        <min_angle>-3.14159</min_angle>
        <max_angle>3.14159</max_angle>
      </horizontal>
    </scan>

    <range>
      <min>0.12</min>
      <max>3.5</max>
      <resolution>0.01</resolution>
    </range>

    <noise>
      <type>gaussian</type>
      <mean>0.0</mean>
      <stddev>0.01</stddev>
    </noise>
  </lidar>
</sensor>

      <visual name="visual">
        <geometry>
          <cylinder>
            <radius>0.10</radius>
            <length>0.08</length>
          </cylinder>
        </geometry>
        <material>
          <ambient>0.8 0.1 0.1 1</ambient>
          <diffuse>0.8 0.1 0.1 1</diffuse>
        </material>
      </visual>
    </link>

    <joint name="lidar_joint" type="fixed">
      <parent>base_link</parent>
      <child>lidar_link</child>
    </joint>

    <plugin filename="libgz-sim-diff-drive-system.so" name="gz::sim::systems::DiffDrive">
      <left_joint>left_wheel_joint</left_joint>
      <right_joint>right_wheel_joint</right_joint>
      <wheel_separation>0.44</wheel_separation>
      <wheel_radius>0.08</wheel_radius>
      <odom_topic>odom</odom_topic>
      <cmd_vel_topic>cmd_vel</cmd_vel_topic>
    </plugin>

  </model>
</sdf>
